<?xml version="1.0"?>
<robot xmlns:xacro="http://www.ros.org/wiki/xacro">

  <xacro:include filename="inertial_macro.xacro" />

  <material name="white">
    <color rgba="1 1 1 1" />
  </material>

  <material name="red">
    <color rgba="1 0 0 1" />
  </material>

  <material name="green">
    <color rgba="0 1 0 1" />
  </material>

  <material name="blue">
    <color rgba="0 0 1 1" />
  </material>

  <material name="black">
    <color rgba="0 0 0 1" />
  </material>

  <!-- BASE LINK -->
  <link name="base_link" />

  <joint name="chassis_joint" type="fixed">
    <parent link="base_link" />
    <child link="chassis" />
    <origin xyz="-0.1 0 0" rpy="0 0 0" />
  </joint>

  <!-- CHASSIS LINK -->
  <link name="chassis">
    <visual>
      <origin xyz="0.24 0 0.195" />
      <geometry>
        <box size="0.48 0.305 0.39" />
      </geometry>
      <material name="blue" />
    </visual>
    <collision>
      <origin xyz="0.24 0 0.195" />
      <geometry>
        <box size="0.48 0.305 0.39" />
      </geometry>
    </collision>
    <xacro:inertial_box mass="5.0" x="0.48" y="0.305" z="0.39">
      <origin xyz="0.24 0 0.195" rpy="0 0 0" />
    </xacro:inertial_box>
  </link>

  <gazebo reference="chassis">
    <material>Gazebo/Blue</material>
  </gazebo>

  <!-- LEFT WHEEL LINK -->

  <joint name="wheel_l_joint" type="continuous">
    <parent link="base_link" />
    <child link="wheel_l" />
    <origin xyz="0.0 0.175 0.0" rpy="-${pi/2} 0 0" />
    <axis xyz="0 0 1" />
  </joint>

  <link name="wheel_l">
    <visual>
      <origin xyz="0 0 0.0" />
      <geometry>
        <cylinder radius="0.05" length="0.04" />
      </geometry>
      <material name="black" />
    </visual>
    <collision>
      <origin xyz="0 0 0.0" />
      <geometry>
        <cylinder radius="0.05" length="0.04" />
      </geometry>
    </collision>
    <xacro:inertial_cylinder mass="0.5" radius="0.05" length="0.04">
      <origin xyz="0 0 0.1" rpy="0 0 0" />
    </xacro:inertial_cylinder>
  </link>

  <gazebo reference="wheel_l">
    <material>Gazebo/Black</material>
  </gazebo>


  <!-- RIGHT WHEEL LINK -->

  <joint name="wheel_r_joint" type="continuous">
    <parent link="base_link" />
    <child link="wheel_r" />
    <origin xyz="0.0 -0.175 0.0" rpy="${pi/2} 0 0" />
    <axis xyz="0 0 -1" />
  </joint>

  <link name="wheel_r">
    <visual>
      <origin xyz="0 0 0.0" />
      <geometry>
        <cylinder radius="0.05" length="0.04" />
      </geometry>
      <material name="black" />
    </visual>
    <collision>
      <origin xyz="0 0 0.0" />
      <geometry>
        <cylinder radius="0.05" length="0.04" />
      </geometry>
    </collision>
    <xacro:inertial_cylinder mass="0.5" radius="0.05" length="0.04" >
      <origin xyz="0 0 0.1" rpy="0 0 0" /> 
    </xacro:inertial_cylinder>
  </link>

  <gazebo reference="wheel_r">
    <material>Gazebo/Black</material>
  </gazebo>

  <!-- CASTER WHEEL LINK -->

  <joint name="wheel_c_joint" type="fixed">
    <parent link="base_link" />
    <child link="wheel_c" />
    <origin xyz="0.24 0 0" />
  </joint>

  <link name="wheel_c">
    <visual>
      <geometry>
        <sphere radius="0.05" />
      </geometry>
      <material name="red" />
    </visual>
    <collision>
      <geometry>
        <sphere radius="0.05" />
      </geometry>
    </collision>
    <xacro:inertial_sphere mass="0.5" radius="0.05">
      <origin xyz="0 0 0" rpy="0 0 0" />
    </xacro:inertial_sphere>
  </link>

  <gazebo reference="wheel_c">
    <material>Gazebo/Red</material>
    <mu1 value="0.001"/>
    <mu2 value="0.001"/>
  </gazebo>

</robot>